Failure # 1 (occurred at 2024-11-11_04-38-01)
Traceback (most recent call last):
  File "/home/atlantis5104/.local/lib/python3.8/site-packages/ray/tune/execution/ray_trial_executor.py", line 996, in get_next_executor_event
    future_result = ray.get(ready_future)
  File "/home/atlantis5104/.local/lib/python3.8/site-packages/ray/_private/client_mode_hook.py", line 105, in wrapper
    return func(*args, **kwargs)
  File "/home/atlantis5104/.local/lib/python3.8/site-packages/ray/_private/worker.py", line 2282, in get
    raise value
ray.exceptions.RayActorError: The actor died because of an error raised in its creation task, [36mray::PPO.__init__()[39m (pid=20928, ip=10.0.0.10, repr=PPO)
  File "/home/atlantis5104/.local/lib/python3.8/site-packages/ray/rllib/evaluation/worker_set.py", line 125, in __init__
    self.add_workers(
  File "/home/atlantis5104/.local/lib/python3.8/site-packages/ray/rllib/evaluation/worker_set.py", line 269, in add_workers
    self.foreach_worker(lambda w: w.assert_healthy())
  File "/home/atlantis5104/.local/lib/python3.8/site-packages/ray/rllib/evaluation/worker_set.py", line 391, in foreach_worker
    remote_results = ray.get([w.apply.remote(func) for w in self.remote_workers()])
ray.exceptions.RayActorError: The actor died because of an error raised in its creation task, [36mray::RolloutWorker.__init__()[39m (pid=20962, ip=10.0.0.10, repr=<ray.rllib.evaluation.rollout_worker.RolloutWorker object at 0x7fa41a2d80a0>)
  File "/home/atlantis5104/.local/lib/python3.8/site-packages/ray/rllib/evaluation/rollout_worker.py", line 490, in __init__
    self.env = env_creator(copy.deepcopy(self.env_context))
  File "/home/atlantis5104/.local/lib/python3.8/site-packages/ray/rllib/algorithms/algorithm.py", line 1902, in <lambda>
    return env_id, lambda cfg: env_specifier(cfg)
  File "pytorch_train_mpc.py", line 74, in __init__
    self.env = QuadrupedGymEnv(time_step=0.001, action_repeat=30, obs_hist_len=5)
  File "/home/atlantis5104/.local/lib/python3.8/site-packages/usc_quadruped_learning-0.0.2-py3.8-linux-x86_64.egg/envs/MPC_task.py", line 77, in __init__
    self.plane = self._pybullet_client.loadURDF("%s/plane.urdf" % self._urdf_root,
pybullet.error: Cannot load URDF file.

During handling of the above exception, another exception occurred:

[36mray::PPO.__init__()[39m (pid=20928, ip=10.0.0.10, repr=PPO)
  File "/home/atlantis5104/.local/lib/python3.8/site-packages/ray/rllib/algorithms/algorithm.py", line 312, in __init__
    super().__init__(config=config, logger_creator=logger_creator, **kwargs)
  File "/home/atlantis5104/.local/lib/python3.8/site-packages/ray/tune/trainable/trainable.py", line 159, in __init__
    self.setup(copy.deepcopy(self.config))
  File "/home/atlantis5104/.local/lib/python3.8/site-packages/ray/rllib/algorithms/algorithm.py", line 447, in setup
    raise e.args[0].args[2]
pybullet.error: Cannot load URDF file.

